{"name": "test_login_2_fail_wrong[testdata0]", "status": "passed", "attachments": [{"name": "log", "source": "379a50dd-2b35-466f-be14-9de88c4d29ee-attachment.txt", "type": "text/plain"}], "parameters": [{"name": "testdata", "value": "{'user_name': '17312783975', 'user_pwd': 'python', 'msg': '此账号没有经过授权，请联系管理员!'}"}], "start": 1582978822657, "stop": 1582978823201, "uuid": "5ece0609-882e-41d1-873f-1080f9cefac6", "historyId": "25cd474fd5ca37a7e712922724366cc3", "testCaseId": "36a98533581576596f44421c5526ef46", "fullName": "TestCases.test_login_new.TestLogin#test_login_2_fail_wrong", "labels": [{"name": "tag", "value": "test"}, {"name": "parentSuite", "value": "TestCases"}, {"name": "suite", "value": "test_login_new"}, {"name": "subSuite", "value": "TestLogin"}, {"name": "host", "value": "Arlen"}, {"name": "thread", "value": "16884-MainThread"}, {"name": "framework", "value": "pytest"}, {"name": "language", "value": "cpython3"}, {"name": "package", "value": "TestCases.test_login_new"}]}